Workbook

Sheet Guide
A1: Spa-Bench Figure Data and Wilson Confidence Intervals
A2: Chart-ready success counts, rates, exact two-sided Wilson 95% intervals, and native Excel charts compiled from the consolidated evaluation workbook.
A4: Wilson z | B4: 1.96
A5: Confidence level | B5: 0.95
A7: Count reconciliation: the five requested model sheets contain 2,891 scored evaluations, one fewer than the 2,892 evaluation rollouts cited for the paper. The separate GR00T action-only sheet contains 20 scored rows and is excluded from every figure here. Resolve the one-rollout discrepancy before publishing a total-episode figure.
A10: Figure / analysis | B10: Required data | C10: Included here | D10: Recommended use | F10: Workbook sheet | G10: Purpose | H10: Chart status
A11: Main benchmark result | B11: Successes, trials, rates, Wilson intervals for novel, familiar, and matched manipulation | C11: Yes | D11: Primary results figure | F11: Overall Summary | G11: Three headline evaluation tracks × three complete models | H11: One native overview chart
A12: Familiar task breakdown | B12: Per-task results for five models, including partial baselines | C12: Yes | D12: Six small-multiple charts | F12: Familiar Data | G12: Six tasks × five models | H12: Feeds six familiar charts
A13: Novel task breakdown | B13: Per-task results for the three complete models | C13: Yes | D13: Six small-multiple charts | F13: Novel Data | G13: Six tasks × three models | H13: Feeds six novel charts
A14: Matched manipulation | B14: Per-task results for the three complete models | C14: Yes | D14: Control analysis; included as chart-ready data | F14: Matched Data | G14: Six tasks × three models | H14: Chart-ready control data
A15: Language robustness | B15: Novel and matched paraphrase outcomes by task/model | C15: Yes | D15: Diagnostic figure or appendix | F15: Diagnostics | G15: Language, object, and no-intervention breakdowns | H15: Chart-ready
A16: Object transfer | B16: Cross-task objects and novel-object pilot outcomes | C16: Yes | D16: Diagnostic figure or appendix | F16: Chart Data | G16: Wide helper blocks with custom error magnitudes | H16: Use for Excel custom error bars
A17: No-intervention | B17: Correct no-op outcomes plus movement-required control | C17: Yes | D17: Safety/action-gating diagnostic | F17: Familiar Charts | G17: Requested familiar-concept charts | H17: Six native charts
A18: Failure taxonomy | B18: Mutually exclusive failure labels per unsuccessful rollout | C18: No | D18: Annotate failures before making this figure | F18: Novel Charts | G18: Requested novel-concept charts | H18: Six native charts
A19: Dataset composition | B19: Demonstrations and evaluation episodes by task/model/split | C19: Partial | D19: Reconcile 2,891 vs. 2,892 first
A20: Missing-cell design | B20: Observed/novel concept–argument cells and demonstrations per cell | C20: No | D20: Build from training-manifest metadata
A22: How to add exact asymmetric Wilson error bars in Excel: select a chart series, choose Custom error bars, set Positive Error Value to the corresponding Upper error row in Chart Data, and Negative Error Value to the Lower error row. The included native charts are intentionally linked to the Success rate rows; all exact CI bounds and error magnitudes remain editable and auditable in the workbook.
A25: Source: Consolidated_Model_Evaluations_with_Custom_Error_Bars.xlsx. Rates use scored Success and Failure rows only. Source condition labels are retained in each data table. Paper-facing labels replace 'withheld' language with capability-oriented evaluation tracks.

Sheet Overall Summary
A1: Overall Success by Evaluation Track
A2: Complete models only. Error columns are the exact asymmetric distances from the observed rate to the Wilson 95% lower and upper bounds.
A4: Evaluation track | B4: Model | C4: Evaluation scope | D4: Success | E4: Failure | F4: Scored | G4: Success rate | H4: CI lower | I4: CI upper | J4: Lower error | K4: Upper error | L4: Wilson 95% CI | M4: Source sheet | N4: Source condition(s) | O4: Notes
A5: Novel Spatial Concepts | B5: MolmoAct2 | C5: Complete benchmark | D5: 156 | E5: 144 | F5: =D5+E5 -> 300 | G5: =IF(F5=0,"",D5/F5) -> 0.52 | H5: =IF(F5=0,"",MAX(0,(G5+Guide!$B$4^2/(2*F5))/(1+Guide!$B$4^2/F5)-Guide!$B$4*SQRT(G5*(1-G5)/F5+Guide!$B$4^2/(4*F5^2))/(1+Guide!$B$4^2/F5))) -> 0.46357005 | I5: =IF(F5=0,"",MIN(1,(G5+Guide!$B$4^2/(2*F5))/(1+Guide!$B$4^2/F5)+Guide!$B$4*SQRT(G5*(1-G5)/F5+Guide!$B$4^2/(4*F5^2))/(1+Guide!$B$4^2/F5))) -> 0.57592421 | J5: =IF(F5=0,"",G5-H5) -> 0.056429946 | K5: =IF(F5=0,"",I5-G5) -> 0.055924209 | L5: =IF(F5=0,"",TEXT(G5,"0.0%")&" ["&TEXT(H5,"0.0%")&"–"&TEXT(I5,"0.0%")&"]") -> 52.0% [46.4%–57.6%] | M5: MolmoAct2 | N5: Concept/compositional transfer | O5: Primary spatial-generalization track; 50 trials per task and model.
A6: Novel Spatial Concepts | B6: π0.5 | C6: Complete benchmark | D6: 122 | E6: 178 | F6: =D6+E6 -> 300 | G6: =IF(F6=0,"",D6/F6) -> 0.40666667 | H6: =IF(F6=0,"",MAX(0,(G6+Guide!$B$4^2/(2*F6))/(1+Guide!$B$4^2/F6)-Guide!$B$4*SQRT(G6*(1-G6)/F6+Guide!$B$4^2/(4*F6^2))/(1+Guide!$B$4^2/F6))) -> 0.3526008 | I6: =IF(F6=0,"",MIN(1,(G6+Guide!$B$4^2/(2*F6))/(1+Guide!$B$4^2/F6)+Guide!$B$4*SQRT(G6*(1-G6)/F6+Guide!$B$4^2/(4*F6^2))/(1+Guide!$B$4^2/F6))) -> 0.46309264 | J6: =IF(F6=0,"",G6-H6) -> 0.054065867 | K6: =IF(F6=0,"",I6-G6) -> 0.056425974 | L6: =IF(F6=0,"",TEXT(G6,"0.0%")&" ["&TEXT(H6,"0.0%")&"–"&TEXT(I6,"0.0%")&"]") -> 40.7% [35.3%–46.3%] | M6: Pi0.5 | N6: Concept/compositional transfer | O6: Primary spatial-generalization track; 50 trials per task and model.
A7: Novel Spatial Concepts | B7: GR00T Vision | C7: Complete benchmark | D7: 133 | E7: 167 | F7: =D7+E7 -> 300 | G7: =IF(F7=0,"",D7/F7) -> 0.44333333 | H7: =IF(F7=0,"",MAX(0,(G7+Guide!$B$4^2/(2*F7))/(1+Guide!$B$4^2/F7)-Guide!$B$4*SQRT(G7*(1-G7)/F7+Guide!$B$4^2/(4*F7^2))/(1+Guide!$B$4^2/F7))) -> 0.38818593 | I7: =IF(F7=0,"",MIN(1,(G7+Guide!$B$4^2/(2*F7))/(1+Guide!$B$4^2/F7)+Guide!$B$4*SQRT(G7*(1-G7)/F7+Guide!$B$4^2/(4*F7^2))/(1+Guide!$B$4^2/F7))) -> 0.49991366 | J7: =IF(F7=0,"",G7-H7) -> 0.055147403 | K7: =IF(F7=0,"",I7-G7) -> 0.056580326 | L7: =IF(F7=0,"",TEXT(G7,"0.0%")&" ["&TEXT(H7,"0.0%")&"–"&TEXT(I7,"0.0%")&"]") -> 44.3% [38.8%–50.0%] | M7: GR00T Vision | N7: Concept/compositional transfer | O7: Primary spatial-generalization track; 50 trials per task and model.
A8: Familiar Spatial Concepts | B8: MolmoAct2 | C8: Complete benchmark | D8: 87 | E8: 33 | F8: =D8+E8 -> 120 | G8: =IF(F8=0,"",D8/F8) -> 0.725 | H8: =IF(F8=0,"",MAX(0,(G8+Guide!$B$4^2/(2*F8))/(1+Guide!$B$4^2/F8)-Guide!$B$4*SQRT(G8*(1-G8)/F8+Guide!$B$4^2/(4*F8^2))/(1+Guide!$B$4^2/F8))) -> 0.63906868 | I8: =IF(F8=0,"",MIN(1,(G8+Guide!$B$4^2/(2*F8))/(1+Guide!$B$4^2/F8)+Guide!$B$4*SQRT(G8*(1-G8)/F8+Guide!$B$4^2/(4*F8^2))/(1+Guide!$B$4^2/F8))) -> 0.7969722 | J8: =IF(F8=0,"",G8-H8) -> 0.085931324 | K8: =IF(F8=0,"",I8-G8) -> 0.071972202 | L8: =IF(F8=0,"",TEXT(G8,"0.0%")&" ["&TEXT(H8,"0.0%")&"–"&TEXT(I8,"0.0%")&"]") -> 72.5% [63.9%–79.7%] | M8: MolmoAct2 | N8: In-distribution concept baseline | O8: Familiar spatial grounding; 20 trials per task and complete model.
A9: Familiar Spatial Concepts | B9: π0.5 | C9: Complete benchmark | D9: 82 | E9: 38 | F9: =D9+E9 -> 120 | G9: =IF(F9=0,"",D9/F9) -> 0.68333333 | H9: =IF(F9=0,"",MAX(0,(G9+Guide!$B$4^2/(2*F9))/(1+Guide!$B$4^2/F9)-Guide!$B$4*SQRT(G9*(1-G9)/F9+Guide!$B$4^2/(4*F9^2))/(1+Guide!$B$4^2/F9))) -> 0.59551965 | I9: =IF(F9=0,"",MIN(1,(G9+Guide!$B$4^2/(2*F9))/(1+Guide!$B$4^2/F9)+Guide!$B$4*SQRT(G9*(1-G9)/F9+Guide!$B$4^2/(4*F9^2))/(1+Guide!$B$4^2/F9))) -> 0.75977292 | J9: =IF(F9=0,"",G9-H9) -> 0.087813687 | K9: =IF(F9=0,"",I9-G9) -> 0.076439587 | L9: =IF(F9=0,"",TEXT(G9,"0.0%")&" ["&TEXT(H9,"0.0%")&"–"&TEXT(I9,"0.0%")&"]") -> 68.3% [59.6%–76.0%] | M9: Pi0.5 | N9: In-distribution concept baseline | O9: Familiar spatial grounding; 20 trials per task and complete model.
A10: Familiar Spatial Concepts | B10: GR00T Vision | C10: Complete benchmark | D10: 81 | E10: 39 | F10: =D10+E10 -> 120 | G10: =IF(F10=0,"",D10/F10) -> 0.675 | H10: =IF(F10=0,"",MAX(0,(G10+Guide!$B$4^2/(2*F10))/(1+Guide!$B$4^2/F10)-Guide!$B$4*SQRT(G10*(1-G10)/F10+Guide!$B$4^2/(4*F10^2))/(1+Guide!$B$4^2/F10))) -> 0.58690017 | I10: =IF(F10=0,"",MIN(1,(G10+Guide!$B$4^2/(2*F10))/(1+Guide!$B$4^2/F10)+Guide!$B$4*SQRT(G10*(1-G10)/F10+Guide!$B$4^2/(4*F10^2))/(1+Guide!$B$4^2/F10))) -> 0.75224274 | J10: =IF(F10=0,"",G10-H10) -> 0.088099831 | K10: =IF(F10=0,"",I10-G10) -> 0.077242736 | L10: =IF(F10=0,"",TEXT(G10,"0.0%")&" ["&TEXT(H10,"0.0%")&"–"&TEXT(I10,"0.0%")&"]") -> 67.5% [58.7%–75.2%] | M10: GR00T Vision | N10: In-distribution concept baseline | O10: Familiar spatial grounding; 20 trials per task and complete model.
A11: Matched Manipulation Control | B11: MolmoAct2 | C11: Complete benchmark | D11: 107 | E11: 13 | F11: =D11+E11 -> 120 | G11: =IF(F11=0,"",D11/F11) -> 0.89166667 | H11: =IF(F11=0,"",MAX(0,(G11+Guide!$B$4^2/(2*F11))/(1+Guide!$B$4^2/F11)-Guide!$B$4*SQRT(G11*(1-G11)/F11+Guide!$B$4^2/(4*F11^2))/(1+Guide!$B$4^2/F11))) -> 0.82344492 | I11: =IF(F11=0,"",MIN(1,(G11+Guide!$B$4^2/(2*F11))/(1+Guide!$B$4^2/F11)+Guide!$B$4*SQRT(G11*(1-G11)/F11+Guide!$B$4^2/(4*F11^2))/(1+Guide!$B$4^2/F11))) -> 0.9355892 | J11: =IF(F11=0,"",G11-H11) -> 0.068221747 | K11: =IF(F11=0,"",I11-G11) -> 0.043922534 | L11: =IF(F11=0,"",TEXT(G11,"0.0%")&" ["&TEXT(H11,"0.0%")&"–"&TEXT(I11,"0.0%")&"]") -> 89.2% [82.3%–93.6%] | M11: MolmoAct2 | N11: Matched manipulation control | O11: Matched motor demand with direct object/action language; 20 trials per task and model.
A12: Matched Manipulation Control | B12: π0.5 | C12: Complete benchmark | D12: 100 | E12: 20 | F12: =D12+E12 -> 120 | G12: =IF(F12=0,"",D12/F12) -> 0.83333333 | H12: =IF(F12=0,"",MAX(0,(G12+Guide!$B$4^2/(2*F12))/(1+Guide!$B$4^2/F12)-Guide!$B$4*SQRT(G12*(1-G12)/F12+Guide!$B$4^2/(4*F12^2))/(1+Guide!$B$4^2/F12))) -> 0.75654561 | I12: =IF(F12=0,"",MIN(1,(G12+Guide!$B$4^2/(2*F12))/(1+Guide!$B$4^2/F12)+Guide!$B$4*SQRT(G12*(1-G12)/F12+Guide!$B$4^2/(4*F12^2))/(1+Guide!$B$4^2/F12))) -> 0.88944088 | J12: =IF(F12=0,"",G12-H12) -> 0.076787727 | K12: =IF(F12=0,"",I12-G12) -> 0.056107547 | L12: =IF(F12=0,"",TEXT(G12,"0.0%")&" ["&TEXT(H12,"0.0%")&"–"&TEXT(I12,"0.0%")&"]") -> 83.3% [75.7%–88.9%] | M12: Pi0.5 | N12: Matched manipulation control | O12: Matched motor demand with direct object/action language; 20 trials per task and model.
A13: Matched Manipulation Control | B13: GR00T Vision | C13: Complete benchmark | D13: 98 | E13: 22 | F13: =D13+E13 -> 120 | G13: =IF(F13=0,"",D13/F13) -> 0.81666667 | H13: =IF(F13=0,"",MAX(0,(G13+Guide!$B$4^2/(2*F13))/(1+Guide!$B$4^2/F13)-Guide!$B$4*SQRT(G13*(1-G13)/F13+Guide!$B$4^2/(4*F13^2))/(1+Guide!$B$4^2/F13))) -> 0.73798926 | I13: =IF(F13=0,"",MIN(1,(G13+Guide!$B$4^2/(2*F13))/(1+Guide!$B$4^2/F13)+Guide!$B$4*SQRT(G13*(1-G13)/F13+Guide!$B$4^2/(4*F13^2))/(1+Guide!$B$4^2/F13))) -> 0.8756979 | J13: =IF(F13=0,"",G13-H13) -> 0.078677403 | K13: =IF(F13=0,"",I13-G13) -> 0.059031231 | L13: =IF(F13=0,"",TEXT(G13,"0.0%")&" ["&TEXT(H13,"0.0%")&"–"&TEXT(I13,"0.0%")&"]") -> 81.7% [73.8%–87.6%] | M13: GR00T Vision | N13: Matched manipulation control | O13: Matched motor demand with direct object/action language; 20 trials per task and model.

Sheet Familiar Data
A1: Familiar Spatial Concepts by Task
A2: Five models are shown. VLA-0 and GR00T full fine-tune are partial familiar-only baselines with unequal task denominators; use the Scored column when comparing them.
A4: Task / Track | B4: Model | C4: Evaluation scope | D4: Success | E4: Failure | F4: Scored | G4: Success rate | H4: CI lower | I4: CI upper | J4: Lower error | K4: Upper error | L4: Wilson 95% CI | M4: Source sheet | N4: Source condition(s) | O4: Notes
A5: State Recognition | B5: MolmoAct2 | C5: Complete benchmark | D5: 18 | E5: 2 | F5: =D5+E5 -> 20 | G5: =IF(F5=0,"",D5/F5) -> 0.9 | H5: =IF(F5=0,"",MAX(0,(G5+Guide!$B$4^2/(2*F5))/(1+Guide!$B$4^2/F5)-Guide!$B$4*SQRT(G5*(1-G5)/F5+Guide!$B$4^2/(4*F5^2))/(1+Guide!$B$4^2/F5))) -> 0.69896179 | I5: =IF(F5=0,"",MIN(1,(G5+Guide!$B$4^2/(2*F5))/(1+Guide!$B$4^2/F5)+Guide!$B$4*SQRT(G5*(1-G5)/F5+Guide!$B$4^2/(4*F5^2))/(1+Guide!$B$4^2/F5))) -> 0.97213411 | J5: =IF(F5=0,"",G5-H5) -> 0.20103821 | K5: =IF(F5=0,"",I5-G5) -> 0.072134106 | L5: =IF(F5=0,"",TEXT(G5,"0.0%")&" ["&TEXT(H5,"0.0%")&"–"&TEXT(I5,"0.0%")&"]") -> 90.0% [69.9%–97.2%] | M5: MolmoAct2 | N5: In-distribution concept baseline
A6: State Recognition | B6: π0.5 | C6: Complete benchmark | D6: 16 | E6: 4 | F6: =D6+E6 -> 20 | G6: =IF(F6=0,"",D6/F6) -> 0.8 | H6: =IF(F6=0,"",MAX(0,(G6+Guide!$B$4^2/(2*F6))/(1+Guide!$B$4^2/F6)-Guide!$B$4*SQRT(G6*(1-G6)/F6+Guide!$B$4^2/(4*F6^2))/(1+Guide!$B$4^2/F6))) -> 0.58397828 | I6: =IF(F6=0,"",MIN(1,(G6+Guide!$B$4^2/(2*F6))/(1+Guide!$B$4^2/F6)+Guide!$B$4*SQRT(G6*(1-G6)/F6+Guide!$B$4^2/(4*F6^2))/(1+Guide!$B$4^2/F6))) -> 0.91934365 | J6: =IF(F6=0,"",G6-H6) -> 0.21602172 | K6: =IF(F6=0,"",I6-G6) -> 0.11934365 | L6: =IF(F6=0,"",TEXT(G6,"0.0%")&" ["&TEXT(H6,"0.0%")&"–"&TEXT(I6,"0.0%")&"]") -> 80.0% [58.4%–91.9%] | M6: Pi0.5 | N6: In-distribution concept baseline
A7: State Recognition | B7: VLA-0 | C7: Partial familiar-only baseline | D7: 0 | E7: 10 | F7: =D7+E7 -> 10 | G7: =IF(F7=0,"",D7/F7) -> 0 | H7: =IF(F7=0,"",MAX(0,(G7+Guide!$B$4^2/(2*F7))/(1+Guide!$B$4^2/F7)-Guide!$B$4*SQRT(G7*(1-G7)/F7+Guide!$B$4^2/(4*F7^2))/(1+Guide!$B$4^2/F7))) -> 0 | I7: =IF(F7=0,"",MIN(1,(G7+Guide!$B$4^2/(2*F7))/(1+Guide!$B$4^2/F7)+Guide!$B$4*SQRT(G7*(1-G7)/F7+Guide!$B$4^2/(4*F7^2))/(1+Guide!$B$4^2/F7))) -> 0.27754017 | J7: =IF(F7=0,"",G7-H7) -> 0 | K7: =IF(F7=0,"",I7-G7) -> 0.27754017 | L7: =IF(F7=0,"",TEXT(G7,"0.0%")&" ["&TEXT(H7,"0.0%")&"–"&TEXT(I7,"0.0%")&"]") -> 0.0% [0.0%–27.8%] | M7: VLA-0 | N7: In-distribution concept baseline | O7: Partial baseline; denominator differs from complete models.
A8: State Recognition | B8: GR00T Full FT | C8: Partial familiar-only baseline | D8: 4 | E8: 16 | F8: =D8+E8 -> 20 | G8: =IF(F8=0,"",D8/F8) -> 0.2 | H8: =IF(F8=0,"",MAX(0,(G8+Guide!$B$4^2/(2*F8))/(1+Guide!$B$4^2/F8)-Guide!$B$4*SQRT(G8*(1-G8)/F8+Guide!$B$4^2/(4*F8^2))/(1+Guide!$B$4^2/F8))) -> 0.080656353 | I8: =IF(F8=0,"",MIN(1,(G8+Guide!$B$4^2/(2*F8))/(1+Guide!$B$4^2/F8)+Guide!$B$4*SQRT(G8*(1-G8)/F8+Guide!$B$4^2/(4*F8^2))/(1+Guide!$B$4^2/F8))) -> 0.41602172 | J8: =IF(F8=0,"",G8-H8) -> 0.11934365 | K8: =IF(F8=0,"",I8-G8) -> 0.21602172 | L8: =IF(F8=0,"",TEXT(G8,"0.0%")&" ["&TEXT(H8,"0.0%")&"–"&TEXT(I8,"0.0%")&"]") -> 20.0% [8.1%–41.6%] | M8: GR00T Full | N8: In-distribution concept baseline | O8: Partial baseline; denominator differs from complete models.
A9: State Recognition | B9: GR00T Vision | C9: Complete benchmark | D9: 17 | E9: 3 | F9: =D9+E9 -> 20 | G9: =IF(F9=0,"",D9/F9) -> 0.85 | H9: =IF(F9=0,"",MAX(0,(G9+Guide!$B$4^2/(2*F9))/(1+Guide!$B$4^2/F9)-Guide!$B$4*SQRT(G9*(1-G9)/F9+Guide!$B$4^2/(4*F9^2))/(1+Guide!$B$4^2/F9))) -> 0.6395767 | I9: =IF(F9=0,"",MIN(1,(G9+Guide!$B$4^2/(2*F9))/(1+Guide!$B$4^2/F9)+Guide!$B$4*SQRT(G9*(1-G9)/F9+Guide!$B$4^2/(4*F9^2))/(1+Guide!$B$4^2/F9))) -> 0.94763221 | J9: =IF(F9=0,"",G9-H9) -> 0.2104233 | K9: =IF(F9=0,"",I9-G9) -> 0.097632208 | L9: =IF(F9=0,"",TEXT(G9,"0.0%")&" ["&TEXT(H9,"0.0%")&"–"&TEXT(I9,"0.0%")&"]") -> 85.0% [64.0%–94.8%] | M9: GR00T Vision | N9: In-distribution concept baseline
A10: Counting | B10: MolmoAct2 | C10: Complete benchmark | D10: 12 | E10: 8 | F10: =D10+E10 -> 20 | G10: =IF(F10=0,"",D10/F10) -> 0.6 | H10: =IF(F10=0,"",MAX(0,(G10+Guide!$B$4^2/(2*F10))/(1+Guide!$B$4^2/F10)-Guide!$B$4*SQRT(G10*(1-G10)/F10+Guide!$B$4^2/(4*F10^2))/(1+Guide!$B$4^2/F10))) -> 0.38657794 | I10: =IF(F10=0,"",MIN(1,(G10+Guide!$B$4^2/(2*F10))/(1+Guide!$B$4^2/F10)+Guide!$B$4*SQRT(G10*(1-G10)/F10+Guide!$B$4^2/(4*F10^2))/(1+Guide!$B$4^2/F10))) -> 0.78119603 | J10: =IF(F10=0,"",G10-H10) -> 0.21342206 | K10: =IF(F10=0,"",I10-G10) -> 0.18119603 | L10: =IF(F10=0,"",TEXT(G10,"0.0%")&" ["&TEXT(H10,"0.0%")&"–"&TEXT(I10,"0.0%")&"]") -> 60.0% [38.7%–78.1%] | M10: MolmoAct2 | N10: In-distribution concept baseline
A11: Counting | B11: π0.5 | C11: Complete benchmark | D11: 11 | E11: 9 | F11: =D11+E11 -> 20 | G11: =IF(F11=0,"",D11/F11) -> 0.55 | H11: =IF(F11=0,"",MAX(0,(G11+Guide!$B$4^2/(2*F11))/(1+Guide!$B$4^2/F11)-Guide!$B$4*SQRT(G11*(1-G11)/F11+Guide!$B$4^2/(4*F11^2))/(1+Guide!$B$4^2/F11))) -> 0.34208201 | I11: =IF(F11=0,"",MIN(1,(G11+Guide!$B$4^2/(2*F11))/(1+Guide!$B$4^2/F11)+Guide!$B$4*SQRT(G11*(1-G11)/F11+Guide!$B$4^2/(4*F11^2))/(1+Guide!$B$4^2/F11))) -> 0.74180498 | J11: =IF(F11=0,"",G11-H11) -> 0.20791799 | K11: =IF(F11=0,"",I11-G11) -> 0.19180498 | L11: =IF(F11=0,"",TEXT(G11,"0.0%")&" ["&TEXT(H11,"0.0%")&"–"&TEXT(I11,"0.0%")&"]") -> 55.0% [34.2%–74.2%] | M11: Pi0.5 | N11: In-distribution concept baseline
A12: Counting | B12: VLA-0 | C12: Partial familiar-only baseline | D12: 0 | E12: 10 | F12: =D12+E12 -> 10 | G12: =IF(F12=0,"",D12/F12) -> 0 | H12: =IF(F12=0,"",MAX(0,(G12+Guide!$B$4^2/(2*F12))/(1+Guide!$B$4^2/F12)-Guide!$B$4*SQRT(G12*(1-G12)/F12+Guide!$B$4^2/(4*F12^2))/(1+Guide!$B$4^2/F12))) -> 0 | I12: =IF(F12=0,"",MIN(1,(G12+Guide!$B$4^2/(2*F12))/(1+Guide!$B$4^2/F12)+Guide!$B$4*SQRT(G12*(1-G12)/F12+Guide!$B$4^2/(4*F12^2))/(1+Guide!$B$4^2/F12))) -> 0.27754017 | J12: =IF(F12=0,"",G12-H12) -> 0 | K12: =IF(F12=0,"",I12-G12) -> 0.27754017 | L12: =IF(F12=0,"",TEXT(G12,"0.0%")&" ["&TEXT(H12,"0.0%")&"–"&TEXT(I12,"0.0%")&"]") -> 0.0% [0.0%–27.8%] | M12: VLA-0 | N12: In-distribution concept baseline | O12: Partial baseline; denominator differs from complete models.
A13: Counting | B13: GR00T Full FT | C13: Partial familiar-only baseline | D13: 7 | E13: 12 | F13: =D13+E13 -> 19 | G13: =IF(F13=0,"",D13/F13) -> 0.36842105 | H13: =IF(F13=0,"",MAX(0,(G13+Guide!$B$4^2/(2*F13))/(1+Guide!$B$4^2/F13)-Guide!$B$4*SQRT(G13*(1-G13)/F13+Guide!$B$4^2/(4*F13^2))/(1+Guide!$B$4^2/F13))) -> 0.19149272 | I13: =IF(F13=0,"",MIN(1,(G13+Guide!$B$4^2/(2*F13))/(1+Guide!$B$4^2/F13)+Guide!$B$4*SQRT(G13*(1-G13)/F13+Guide!$B$4^2/(4*F13^2))/(1+Guide!$B$4^2/F13))) -> 0.58960843 | J13: =IF(F13=0,"",G13-H13) -> 0.17692833 | K13: =IF(F13=0,"",I13-G13) -> 0.22118737 | L13: =IF(F13=0,"",TEXT(G13,"0.0%")&" ["&TEXT(H13,"0.0%")&"–"&TEXT(I13,"0.0%")&"]") -> 36.8% [19.1%–59.0%] | M13: GR00T Full | N13: In-distribution concept baseline | O13: Partial baseline; denominator differs from complete models.
A14: Counting | B14: GR00T Vision | C14: Complete benchmark | D14: 12 | E14: 8 | F14: =D14+E14 -> 20 | G14: =IF(F14=0,"",D14/F14) -> 0.6 | H14: =IF(F14=0,"",MAX(0,(G14+Guide!$B$4^2/(2*F14))/(1+Guide!$B$4^2/F14)-Guide!$B$4*SQRT(G14*(1-G14)/F14+Guide!$B$4^2/(4*F14^2))/(1+Guide!$B$4^2/F14))) -> 0.38657794 | I14: =IF(F14=0,"",MIN(1,(G14+Guide!$B$4^2/(2*F14))/(1+Guide!$B$4^2/F14)+Guide!$B$4*SQRT(G14*(1-G14)/F14+Guide!$B$4^2/(4*F14^2))/(1+Guide!$B$4^2/F14))) -> 0.78119603 | J14: =IF(F14=0,"",G14-H14) -> 0.21342206 | K14: =IF(F14=0,"",I14-G14) -> 0.18119603 | L14: =IF(F14=0,"",TEXT(G14,"0.0%")&" ["&TEXT(H14,"0.0%")&"–"&TEXT(I14,"0.0%")&"]") -> 60.0% [38.7%–78.1%] | M14: GR00T Vision | N14: In-distribution concept baseline
A15: Ordinal Reference Ordering | B15: MolmoAct2 | C15: Complete benchmark | D15: 10 | E15: 10 | F15: =D15+E15 -> 20 | G15: =IF(F15=0,"",D15/F15) -> 0.5 | H15: =IF(F15=0,"",MAX(0,(G15+Guide!$B$4^2/(2*F15))/(1+Guide!$B$4^2/F15)-Guide!$B$4*SQRT(G15*(1-G15)/F15+Guide!$B$4^2/(4*F15^2))/(1+Guide!$B$4^2/F15))) -> 0.29929491 | I15: =IF(F15=0,"",MIN(1,(G15+Guide!$B$4^2/(2*F15))/(1+Guide!$B$4^2/F15)+Guide!$B$4*SQRT(G15*(1-G15)/F15+Guide!$B$4^2/(4*F15^2))/(1+Guide!$B$4^2/F15))) -> 0.70070509 | J15: =IF(F15=0,"",G15-H15) -> 0.20070509 | K15: =IF(F15=0,"",I15-G15) -> 0.20070509 | L15: =IF(F15=0,"",TEXT(G15,"0.0%")&" ["&TEXT(H15,"0.0%")&"–"&TEXT(I15,"0.0%")&"]") -> 50.0% [29.9%–70.1%] | M15: MolmoAct2 | N15: In-distribution concept baseline
A16: Ordinal Reference Ordering | B16: π0.5 | C16: Complete benchmark | D16: 7 | E16: 13 | F16: =D16+E16 -> 20 | G16: =IF(F16=0,"",D16/F16) -> 0.35 | H16: =IF(F16=0,"",MAX(0,(G16+Guide!$B$4^2/(2*F16))/(1+Guide!$B$4^2/F16)-Guide!$B$4*SQRT(G16*(1-G16)/F16+Guide!$B$4^2/(4*F16^2))/(1+Guide!$B$4^2/F16))) -> 0.18118955 | I16: =IF(F16=0,"",MIN(1,(G16+Guide!$B$4^2/(2*F16))/(1+Guide!$B$4^2/F16)+Guide!$B$4*SQRT(G16*(1-G16)/F16+Guide!$B$4^2/(4*F16^2))/(1+Guide!$B$4^2/F16))) -> 0.56714949 | J16: =IF(F16=0,"",G16-H16) -> 0.16881045 | K16: =IF(F16=0,"",I16-G16) -> 0.21714949 | L16: =IF(F16=0,"",TEXT(G16,"0.0%")&" ["&TEXT(H16,"0.0%")&"–"&TEXT(I16,"0.0%")&"]") -> 35.0% [18.1%–56.7%] | M16: Pi0.5 | N16: In-distribution concept baseline
A17: Ordinal Reference Ordering | B17: VLA-0 | C17: Partial familiar-only baseline | D17: 0 | E17: 10 | F17: =D17+E17 -> 10 | G17: =IF(F17=0,"",D17/F17) -> 0 | H17: =IF(F17=0,"",MAX(0,(G17+Guide!$B$4^2/(2*F17))/(1+Guide!$B$4^2/F17)-Guide!$B$4*SQRT(G17*(1-G17)/F17+Guide!$B$4^2/(4*F17^2))/(1+Guide!$B$4^2/F17))) -> 0 | I17: =IF(F17=0,"",MIN(1,(G17+Guide!$B$4^2/(2*F17))/(1+Guide!$B$4^2/F17)+Guide!$B$4*SQRT(G17*(1-G17)/F17+Guide!$B$4^2/(4*F17^2))/(1+Guide!$B$4^2/F17))) -> 0.27754017 | J17: =IF(F17=0,"",G17-H17) -> 0 | K17: =IF(F17=0,"",I17-G17) -> 0.27754017 | L17: =IF(F17=0,"",TEXT(G17,"0.0%")&" ["&TEXT(H17,"0.0%")&"–"&TEXT(I17,"0.0%")&"]") -> 0.0% [0.0%–27.8%] | M17: VLA-0 | N17: In-distribution concept baseline | O17: Partial baseline; denominator differs from complete models.
A18: Ordinal Reference Ordering | B18: GR00T Full FT | C18: Partial familiar-only baseline | D18: 3 | E18: 17 | F18: =D18+E18 -> 20 | G18: =IF(F18=0,"",D18/F18) -> 0.15 | H18: =IF(F18=0,"",MAX(0,(G18+Guide!$B$4^2/(2*F18))/(1+Guide!$B$4^2/F18)-Guide!$B$4*SQRT(G18*(1-G18)/F18+Guide!$B$4^2/(4*F18^2))/(1+Guide!$B$4^2/F18))) -> 0.052367792 | I18: =IF(F18=0,"",MIN(1,(G18+Guide!$B$4^2/(2*F18))/(1+Guide!$B$4^2/F18)+Guide!$B$4*SQRT(G18*(1-G18)/F18+Guide!$B$4^2/(4*F18^2))/(1+Guide!$B$4^2/F18))) -> 0.3604233 | J18: =IF(F18=0,"",G18-H18) -> 0.097632208 | K18: =IF(F18=0,"",I18-G18) -> 0.2104233 | L18: =IF(F18=0,"",TEXT(G18,"0.0%")&" ["&TEXT(H18,"0.0%")&"–"&TEXT(I18,"0.0%")&"]") -> 15.0% [5.2%–36.0%] | M18: GR00T Full | N18: In-distribution concept baseline | O18: Partial baseline; denominator differs from complete models.
A19: Ordinal Reference Ordering | B19: GR00T Vision | C19: Complete benchmark | D19: 9 | E19: 11 | F19: =D19+E19 -> 20 | G19: =IF(F19=0,"",D19/F19) -> 0.45 | H19: =IF(F19=0,"",MAX(0,(G19+Guide!$B$4^2/(2*F19))/(1+Guide!$B$4^2/F19)-Guide!$B$4*SQRT(G19*(1-G19)/F19+Guide!$B$4^2/(4*F19^2))/(1+Guide!$B$4^2/F19))) -> 0.25819502 | I19: =IF(F19=0,"",MIN(1,(G19+Guide!$B$4^2/(2*F19))/(1+Guide!$B$4^2/F19)+Guide!$B$4*SQRT(G19*(1-G19)/F19+Guide!$B$4^2/(4*F19^2))/(1+Guide!$B$4^2/F19))) -> 0.65791799 | J19: =IF(F19=0,"",G19-H19) -> 0.19180498 | K19: =IF(F19=0,"",I19-G19) -> 0.20791799 | L19: =IF(F19=0,"",TEXT(G19,"0.0%")&" ["&TEXT(H19,"0.0%")&"–"&TEXT(I19,"0.0%")&"]") -> 45.0% [25.8%–65.8%] | M19: GR00T Vision | N19: In-distribution concept baseline
A20: Relational Placement | B20: MolmoAct2 | C20: Complete benchmark | D20: 16 | E20: 4 | F20: =D20+E20 -> 20 | G20: =IF(F20=0,"",D20/F20) -> 0.8 | H20: =IF(F20=0,"",MAX(0,(G20+Guide!$B$4^2/(2*F20))/(1+Guide!$B$4^2/F20)-Guide!$B$4*SQRT(G20*(1-G20)/F20+Guide!$B$4^2/(4*F20^2))/(1+Guide!$B$4^2/F20))) -> 0.58397828 | I20: =IF(F20=0,"",MIN(1,(G20+Guide!$B$4^2/(2*F20))/(1+Guide!$B$4^2/F20)+Guide!$B$4*SQRT(G20*(1-G20)/F20+Guide!$B$4^2/(4*F20^2))/(1+Guide!$B$4^2/F20))) -> 0.91934365 | J20: =IF(F20=0,"",G20-H20) -> 0.21602172 | K20: =IF(F20=0,"",I20-G20) -> 0.11934365 | L20: =IF(F20=0,"",TEXT(G20,"0.0%")&" ["&TEXT(H20,"0.0%")&"–"&TEXT(I20,"0.0%")&"]") -> 80.0% [58.4%–91.9%] | M20: MolmoAct2 | N20: In-distribution concept baseline
A21: Relational Placement | B21: π0.5 | C21: Complete benchmark | D21: 13 | E21: 7 | F21: =D21+E21 -> 20 | G21: =IF(F21=0,"",D21/F21) -> 0.65 | H21: =IF(F21=0,"",MAX(0,(G21+Guide!$B$4^2/(2*F21))/(1+Guide!$B$4^2/F21)-Guide!$B$4*SQRT(G21*(1-G21)/F21+Guide!$B$4^2/(4*F21^2))/(1+Guide!$B$4^2/F21))) -> 0.43285051 | I21: =IF(F21=0,"",MIN(1,(G21+Guide!$B$4^2/(2*F21))/(1+Guide!$B$4^2/F21)+Guide!$B$4*SQRT(G21*(1-G21)/F21+Guide!$B$4^2/(4*F21^2))/(1+Guide!$B$4^2/F21))) -> 0.81881045 | J21: =IF(F21=0,"",G21-H21) -> 0.21714949 | K21: =IF(F21=0,"",I21-G21) -> 0.16881045 | L21: =IF(F21=0,"",TEXT(G21,"0.0%")&" ["&TEXT(H21,"0.0%")&"–"&TEXT(I21,"0.0%")&"]") -> 65.0% [43.3%–81.9%] | M21: Pi0.5 | N21: In-distribution concept baseline
A22: Relational Placement | B22: VLA-0 | C22: Partial familiar-only baseline | D22: 0 | E22: 12 | F22: =D22+E22 -> 12 | G22: =IF(F22=0,"",D22/F22) -> 0 | H22: =IF(F22=0,"",MAX(0,(G22+Guide!$B$4^2/(2*F22))/(1+Guide!$B$4^2/F22)-Guide!$B$4*SQRT(G22*(1-G22)/F22+Guide!$B$4^2/(4*F22^2))/(1+Guide!$B$4^2/F22))) -> 0 | I22: =IF(F22=0,"",MIN(1,(G22+Guide!$B$4^2/(2*F22))/(1+Guide!$B$4^2/F22)+Guide!$B$4*SQRT(G22*(1-G22)/F22+Guide!$B$4^2/(4*F22^2))/(1+Guide!$B$4^2/F22))) -> 0.24250076 | J22: =IF(F22=0,"",G22-H22) -> 0 | K22: =IF(F22=0,"",I22-G22) -> 0.24250076 | L22: =IF(F22=0,"",TEXT(G22,"0.0%")&" ["&TEXT(H22,"0.0%")&"–"&TEXT(I22,"0.0%")&"]") -> 0.0% [0.0%–24.3%] | M22: VLA-0 | N22: In-distribution concept baseline | O22: Partial baseline; denominator differs from complete models.
A23: Relational Placement | B23: GR00T Full FT | C23: Partial familiar-only baseline | D23: 0 | E23: 20 | F23: =D23+E23 -> 20 | G23: =IF(F23=0,"",D23/F23) -> 0 | H23: =IF(F23=0,"",MAX(0,(G23+Guide!$B$4^2/(2*F23))/(1+Guide!$B$4^2/F23)-Guide!$B$4*SQRT(G23*(1-G23)/F23+Guide!$B$4^2/(4*F23^2))/(1+Guide!$B$4^2/F23))) -> 0 | I23: =IF(F23=0,"",MIN(1,(G23+Guide!$B$4^2/(2*F23))/(1+Guide!$B$4^2/F23)+Guide!$B$4*SQRT(G23*(1-G23)/F23+Guide!$B$4^2/(4*F23^2))/(1+Guide!$B$4^2/F23))) -> 0.16113013 | J23: =IF(F23=0,"",G23-H23) -> 0 | K23: =IF(F23=0,"",I23-G23) -> 0.16113013 | L23: =IF(F23=0,"",TEXT(G23,"0.0%")&" ["&TEXT(H23,"0.0%")&"–"&TEXT(I23,"0.0%")&"]") -> 0.0% [0.0%–16.1%] | M23: GR00T Full | N23: In-distribution concept baseline | O23: Partial baseline; denominator differs from complete models.
A24: Relational Placement | B24: GR00T Vision | C24: Complete benchmark | D24: 14 | E24: 6 | F24: =D24+E24 -> 20 | G24: =IF(F24=0,"",D24/F24) -> 0.7 | H24: =IF(F24=0,"",MAX(0,(G24+Guide!$B$4^2/(2*F24))/(1+Guide!$B$4^2/F24)-Guide!$B$4*SQRT(G24*(1-G24)/F24+Guide!$B$4^2/(4*F24^2))/(1+Guide!$B$4^2/F24))) -> 0.48102322 | I24: =IF(F24=0,"",MIN(1,(G24+Guide!$B$4^2/(2*F24))/(1+Guide!$B$4^2/F24)+Guide!$B$4*SQRT(G24*(1-G24)/F24+Guide!$B$4^2/(4*F24^2))/(1+Guide!$B$4^2/F24))) -> 0.85452473 | J24: =IF(F24=0,"",G24-H24) -> 0.21897678 | K24: =IF(F24=0,"",I24-G24) -> 0.15452473 | L24: =IF(F24=0,"",TEXT(G24,"0.0%")&" ["&TEXT(H24,"0.0%")&"–"&TEXT(I24,"0.0%")&"]") -> 70.0% [48.1%–85.5%] | M24: GR00T Vision | N24: In-distribution concept baseline
A25: Referential Disambiguation | B25: MolmoAct2 | C25: Complete benchmark | D25: 15 | E25: 5 | F25: =D25+E25 -> 20 | G25: =IF(F25=0,"",D25/F25) -> 0.75 | H25: =IF(F25=0,"",MAX(0,(G25+Guide!$B$4^2/(2*F25))/(1+Guide!$B$4^2/F25)-Guide!$B$4*SQRT(G25*(1-G25)/F25+Guide!$B$4^2/(4*F25^2))/(1+Guide!$B$4^2/F25))) -> 0.53129499 | I25: =IF(F25=0,"",MIN(1,(G25+Guide!$B$4^2/(2*F25))/(1+Guide!$B$4^2/F25)+Guide!$B$4*SQRT(G25*(1-G25)/F25+Guide!$B$4^2/(4*F25^2))/(1+Guide!$B$4^2/F25))) -> 0.88813995 | J25: =IF(F25=0,"",G25-H25) -> 0.21870501 | K25: =IF(F25=0,"",I25-G25) -> 0.13813995 | L25: =IF(F25=0,"",TEXT(G25,"0.0%")&" ["&TEXT(H25,"0.0%")&"–"&TEXT(I25,"0.0%")&"]") -> 75.0% [53.1%–88.8%] | M25: MolmoAct2 | N25: In-distribution concept baseline
A26: Referential Disambiguation | B26: π0.5 | C26: Complete benchmark | D26: 16 | E26: 4 | F26: =D26+E26 -> 20 | G26: =IF(F26=0,"",D26/F26) -> 0.8 | H26: =IF(F26=0,"",MAX(0,(G26+Guide!$B$4^2/(2*F26))/(1+Guide!$B$4^2/F26)-Guide!$B$4*SQRT(G26*(1-G26)/F26+Guide!$B$4^2/(4*F26^2))/(1+Guide!$B$4^2/F26))) -> 0.58397828 | I26: =IF(F26=0,"",MIN(1,(G26+Guide!$B$4^2/(2*F26))/(1+Guide!$B$4^2/F26)+Guide!$B$4*SQRT(G26*(1-G26)/F26+Guide!$B$4^2/(4*F26^2))/(1+Guide!$B$4^2/F26))) -> 0.91934365 | J26: =IF(F26=0,"",G26-H26) -> 0.21602172 | K26: =IF(F26=0,"",I26-G26) -> 0.11934365 | L26: =IF(F26=0,"",TEXT(G26,"0.0%")&" ["&TEXT(H26,"0.0%")&"–"&TEXT(I26,"0.0%")&"]") -> 80.0% [58.4%–91.9%] | M26: Pi0.5 | N26: In-distribution concept baseline
A27: Referential Disambiguation | B27: VLA-0 | C27: Partial familiar-only baseline | D27: 0 | E27: 10 | F27: =D27+E27 -> 10 | G27: =IF(F27=0,"",D27/F27) -> 0 | H27: =IF(F27=0,"",MAX(0,(G27+Guide!$B$4^2/(2*F27))/(1+Guide!$B$4^2/F27)-Guide!$B$4*SQRT(G27*(1-G27)/F27+Guide!$B$4^2/(4*F27^2))/(1+Guide!$B$4^2/F27))) -> 0 | I27: =IF(F27=0,"",MIN(1,(G27+Guide!$B$4^2/(2*F27))/(1+Guide!$B$4^2/F27)+Guide!$B$4*SQRT(G27*(1-G27)/F27+Guide!$B$4^2/(4*F27^2))/(1+Guide!$B$4^2/F27))) -> 0.27754017 | J27: =IF(F27=0,"",G27-H27) -> 0 | K27: =IF(F27=0,"",I27-G27) -> 0.27754017 | L27: =IF(F27=0,"",TEXT(G27,"0.0%")&" ["&TEXT(H27,"0.0%")&"–"&TEXT(I27,"0.0%")&"]") -> 0.0% [0.0%–27.8%] | M27: VLA-0 | N27: In-distribution concept baseline | O27: Partial baseline; denominator differs from complete models.
A28: Referential Disambiguation | B28: GR00T Full FT | C28: Partial familiar-only baseline | D28: 4 | E28: 16 | F28: =D28+E28 -> 20 | G28: =IF(F28=0,"",D28/F28) -> 0.2 | H28: =IF(F28=0,"",MAX(0,(G28+Guide!$B$4^2/(2*F28))/(1+Guide!$B$4^2/F28)-Guide!$B$4*SQRT(G28*(1-G28)/F28+Guide!$B$4^2/(4*F28^2))/(1+Guide!$B$4^2/F28))) -> 0.080656353 | I28: =IF(F28=0,"",MIN(1,(G28+Guide!$B$4^2/(2*F28))/(1+Guide!$B$4^2/F28)+Guide!$B$4*SQRT(G28*(1-G28)/F28+Guide!$B$4^2/(4*F28^2))/(1+Guide!$B$4^2/F28))) -> 0.41602172 | J28: =IF(F28=0,"",G28-H28) -> 0.11934365 | K28: =IF(F28=0,"",I28-G28) -> 0.21602172 | L28: =IF(F28=0,"",TEXT(G28,"0.0%")&" ["&TEXT(H28,"0.0%")&"–"&TEXT(I28,"0.0%")&"]") -> 20.0% [8.1%–41.6%] | M28: GR00T Full | N28: In-distribution concept baseline | O28: Partial baseline; denominator differs from complete models.
A29: Referential Disambiguation | B29: GR00T Vision | C29: Complete benchmark | D29: 12 | E29: 8 | F29: =D29+E29 -> 20 | G29: =IF(F29=0,"",D29/F29) -> 0.6 | H29: =IF(F29=0,"",MAX(0,(G29+Guide!$B$4^2/(2*F29))/(1+Guide!$B$4^2/F29)-Guide!$B$4*SQRT(G29*(1-G29)/F29+Guide!$B$4^2/(4*F29^2))/(1+Guide!$B$4^2/F29))) -> 0.38657794 | I29: =IF(F29=0,"",MIN(1,(G29+Guide!$B$4^2/(2*F29))/(1+Guide!$B$4^2/F29)+Guide!$B$4*SQRT(G29*(1-G29)/F29+Guide!$B$4^2/(4*F29^2))/(1+Guide!$B$4^2/F29))) -> 0.78119603 | J29: =IF(F29=0,"",G29-H29) -> 0.21342206 | K29: =IF(F29=0,"",I29-G29) -> 0.18119603 | L29: =IF(F29=0,"",TEXT(G29,"0.0%")&" ["&TEXT(H29,"0.0%")&"–"&TEXT(I29,"0.0%")&"]") -> 60.0% [38.7%–78.1%] | M29: GR00T Vision | N29: In-distribution concept baseline
A30: Size Recognition | B30: MolmoAct2 | C30: Complete benchmark | D30: 16 | E30: 4 | F30: =D30+E30 -> 20 | G30: =IF(F30=0,"",D30/F30) -> 0.8 | H30: =IF(F30=0,"",MAX(0,(G30+Guide!$B$4^2/(2*F30))/(1+Guide!$B$4^2/F30)-Guide!$B$4*SQRT(G30*(1-G30)/F30+Guide!$B$4^2/(4*F30^2))/(1+Guide!$B$4^2/F30))) -> 0.58397828 | I30: =IF(F30=0,"",MIN(1,(G30+Guide!$B$4^2/(2*F30))/(1+Guide!$B$4^2/F30)+Guide!$B$4*SQRT(G30*(1-G30)/F30+Guide!$B$4^2/(4*F30^2))/(1+Guide!$B$4^2/F30))) -> 0.91934365 | J30: =IF(F30=0,"",G30-H30) -> 0.21602172 | K30: =IF(F30=0,"",I30-G30) -> 0.11934365 | L30: =IF(F30=0,"",TEXT(G30,"0.0%")&" ["&TEXT(H30,"0.0%")&"–"&TEXT(I30,"0.0%")&"]") -> 80.0% [58.4%–91.9%] | M30: MolmoAct2 | N30: In-distribution concept baseline
A31: Size Recognition | B31: π0.5 | C31: Complete benchmark | D31: 19 | E31: 1 | F31: =D31+E31 -> 20 | G31: =IF(F31=0,"",D31/F31) -> 0.95 | H31: =IF(F31=0,"",MAX(0,(G31+Guide!$B$4^2/(2*F31))/(1+Guide!$B$4^2/F31)-Guide!$B$4*SQRT(G31*(1-G31)/F31+Guide!$B$4^2/(4*F31^2))/(1+Guide!$B$4^2/F31))) -> 0.76386411 | I31: =IF(F31=0,"",MIN(1,(G31+Guide!$B$4^2/(2*F31))/(1+Guide!$B$4^2/F31)+Guide!$B$4*SQRT(G31*(1-G31)/F31+Guide!$B$4^2/(4*F31^2))/(1+Guide!$B$4^2/F31))) -> 0.99111878 | J31: =IF(F31=0,"",G31-H31) -> 0.18613589 | K31: =IF(F31=0,"",I31-G31) -> 0.041118781 | L31: =IF(F31=0,"",TEXT(G31,"0.0%")&" ["&TEXT(H31,"0.0%")&"–"&TEXT(I31,"0.0%")&"]") -> 95.0% [76.4%–99.1%] | M31: Pi0.5 | N31: In-distribution concept baseline
A32: Size Recognition | B32: VLA-0 | C32: Partial familiar-only baseline | D32: 0 | E32: 20 | F32: =D32+E32 -> 20 | G32: =IF(F32=0,"",D32/F32) -> 0 | H32: =IF(F32=0,"",MAX(0,(G32+Guide!$B$4^2/(2*F32))/(1+Guide!$B$4^2/F32)-Guide!$B$4*SQRT(G32*(1-G32)/F32+Guide!$B$4^2/(4*F32^2))/(1+Guide!$B$4^2/F32))) -> 0 | I32: =IF(F32=0,"",MIN(1,(G32+Guide!$B$4^2/(2*F32))/(1+Guide!$B$4^2/F32)+Guide!$B$4*SQRT(G32*(1-G32)/F32+Guide!$B$4^2/(4*F32^2))/(1+Guide!$B$4^2/F32))) -> 0.16113013 | J32: =IF(F32=0,"",G32-H32) -> 0 | K32: =IF(F32=0,"",I32-G32) -> 0.16113013 | L32: =IF(F32=0,"",TEXT(G32,"0.0%")&" ["&TEXT(H32,"0.0%")&"–"&TEXT(I32,"0.0%")&"]") -> 0.0% [0.0%–16.1%] | M32: VLA-0 | N32: In-distribution concept baseline | O32: Partial baseline; denominator differs from complete models.
A33: Size Recognition | B33: GR00T Full FT | C33: Partial familiar-only baseline | D33: 7 | E33: 13 | F33: =D33+E33 -> 20 | G33: =IF(F33=0,"",D33/F33) -> 0.35 | H33: =IF(F33=0,"",MAX(0,(G33+Guide!$B$4^2/(2*F33))/(1+Guide!$B$4^2/F33)-Guide!$B$4*SQRT(G33*(1-G33)/F33+Guide!$B$4^2/(4*F33^2))/(1+Guide!$B$4^2/F33))) -> 0.18118955 | I33: =IF(F33=0,"",MIN(1,(G33+Guide!$B$4^2/(2*F33))/(1+Guide!$B$4^2/F33)+Guide!$B$4*SQRT(G33*(1-G33)/F33+Guide!$B$4^2/(4*F33^2))/(1+Guide!$B$4^2/F33))) -> 0.56714949 | J33: =IF(F33=0,"",G33-H33) -> 0.16881045 | K33: =IF(F33=0,"",I33-G33) -> 0.21714949 | L33: =IF(F33=0,"",TEXT(G33,"0.0%")&" ["&TEXT(H33,"0.0%")&"–"&TEXT(I33,"0.0%")&"]") -> 35.0% [18.1%–56.7%] | M33: GR00T Full | N33: In-distribution concept baseline | O33: Partial baseline; denominator differs from complete models.
A34: Size Recognition | B34: GR00T Vision | C34: Complete benchmark | D34: 17 | E34: 3 | F34: =D34+E34 -> 20 | G34: =IF(F34=0,"",D34/F34) -> 0.85 | H34: =IF(F34=0,"",MAX(0,(G34+Guide!$B$4^2/(2*F34))/(1+Guide!$B$4^2/F34)-Guide!$B$4*SQRT(G34*(1-G34)/F34+Guide!$B$4^2/(4*F34^2))/(1+Guide!$B$4^2/F34))) -> 0.6395767 | I34: =IF(F34=0,"",MIN(1,(G34+Guide!$B$4^2/(2*F34))/(1+Guide!$B$4^2/F34)+Guide!$B$4*SQRT(G34*(1-G34)/F34+Guide!$B$4^2/(4*F34^2))/(1+Guide!$B$4^2/F34))) -> 0.94763221 | J34: =IF(F34=0,"",G34-H34) -> 0.2104233 | K34: =IF(F34=0,"",I34-G34) -> 0.097632208 | L34: =IF(F34=0,"",TEXT(G34,"0.0%")&" ["&TEXT(H34,"0.0%")&"–"&TEXT(I34,"0.0%")&"]") -> 85.0% [64.0%–94.8%] | M34: GR00T Vision | N34: In-distribution concept baseline

Sheet Novel Data
A1: Novel Spatial Concepts by Task
A2: Three complete models; 50 physical robot trials per task and model.
A4: Task / Track | B4: Model | C4: Evaluation scope | D4: Success | E4: Failure | F4: Scored | G4: Success rate | H4: CI lower | I4: CI upper | J4: Lower error | K4: Upper error | L4: Wilson 95% CI | M4: Source sheet | N4: Source condition(s) | O4: Notes
A5: State Recognition | B5: MolmoAct2 | C5: Complete benchmark | D5: 38 | E5: 12 | F5: =D5+E5 -> 50 | G5: =IF(F5=0,"",D5/F5) -> 0.76 | H5: =IF(F5=0,"",MAX(0,(G5+Guide!$B$4^2/(2*F5))/(1+Guide!$B$4^2/F5)-Guide!$B$4*SQRT(G5*(1-G5)/F5+Guide!$B$4^2/(4*F5^2))/(1+Guide!$B$4^2/F5))) -> 0.62587051 | I5: =IF(F5=0,"",MIN(1,(G5+Guide!$B$4^2/(2*F5))/(1+Guide!$B$4^2/F5)+Guide!$B$4*SQRT(G5*(1-G5)/F5+Guide!$B$4^2/(4*F5^2))/(1+Guide!$B$4^2/F5))) -> 0.85702748 | J5: =IF(F5=0,"",G5-H5) -> 0.13412949 | K5: =IF(F5=0,"",I5-G5) -> 0.097027476 | L5: =IF(F5=0,"",TEXT(G5,"0.0%")&" ["&TEXT(H5,"0.0%")&"–"&TEXT(I5,"0.0%")&"]") -> 76.0% [62.6%–85.7%] | M5: MolmoAct2 | N5: Concept/compositional transfer
A6: State Recognition | B6: π0.5 | C6: Complete benchmark | D6: 18 | E6: 32 | F6: =D6+E6 -> 50 | G6: =IF(F6=0,"",D6/F6) -> 0.36 | H6: =IF(F6=0,"",MAX(0,(G6+Guide!$B$4^2/(2*F6))/(1+Guide!$B$4^2/F6)-Guide!$B$4*SQRT(G6*(1-G6)/F6+Guide!$B$4^2/(4*F6^2))/(1+Guide!$B$4^2/F6))) -> 0.24138563 | I6: =IF(F6=0,"",MIN(1,(G6+Guide!$B$4^2/(2*F6))/(1+Guide!$B$4^2/F6)+Guide!$B$4*SQRT(G6*(1-G6)/F6+Guide!$B$4^2/(4*F6^2))/(1+Guide!$B$4^2/F6))) -> 0.49859238 | J6: =IF(F6=0,"",G6-H6) -> 0.11861437 | K6: =IF(F6=0,"",I6-G6) -> 0.13859238 | L6: =IF(F6=0,"",TEXT(G6,"0.0%")&" ["&TEXT(H6,"0.0%")&"–"&TEXT(I6,"0.0%")&"]") -> 36.0% [24.1%–49.9%] | M6: Pi0.5 | N6: Concept/compositional transfer
A7: State Recognition | B7: GR00T Vision | C7: Complete benchmark | D7: 17 | E7: 33 | F7: =D7+E7 -> 50 | G7: =IF(F7=0,"",D7/F7) -> 0.34 | H7: =IF(F7=0,"",MAX(0,(G7+Guide!$B$4^2/(2*F7))/(1+Guide!$B$4^2/F7)-Guide!$B$4*SQRT(G7*(1-G7)/F7+Guide!$B$4^2/(4*F7^2))/(1+Guide!$B$4^2/F7))) -> 0.2243677 | I7: =IF(F7=0,"",MIN(1,(G7+Guide!$B$4^2/(2*F7))/(1+Guide!$B$4^2/F7)+Guide!$B$4*SQRT(G7*(1-G7)/F7+Guide!$B$4^2/(4*F7^2))/(1+Guide!$B$4^2/F7))) -> 0.47846431 | J7: =IF(F7=0,"",G7-H7) -> 0.1156323 | K7: =IF(F7=0,"",I7-G7) -> 0.13846431 | L7: =IF(F7=0,"",TEXT(G7,"0.0%")&" ["&TEXT(H7,"0.0%")&"–"&TEXT(I7,"0.0%")&"]") -> 34.0% [22.4%–47.8%] | M7: GR00T Vision | N7: Concept/compositional transfer
A8: Counting | B8: MolmoAct2 | C8: Complete benchmark | D8: 0 | E8: 50 | F8: =D8+E8 -> 50 | G8: =IF(F8=0,"",D8/F8) -> 0 | H8: =IF(F8=0,"",MAX(0,(G8+Guide!$B$4^2/(2*F8))/(1+Guide!$B$4^2/F8)-Guide!$B$4*SQRT(G8*(1-G8)/F8+Guide!$B$4^2/(4*F8^2))/(1+Guide!$B$4^2/F8))) -> 0 | I8: =IF(F8=0,"",MIN(1,(G8+Guide!$B$4^2/(2*F8))/(1+Guide!$B$4^2/F8)+Guide!$B$4*SQRT(G8*(1-G8)/F8+Guide!$B$4^2/(4*F8^2))/(1+Guide!$B$4^2/F8))) -> 0.071350034 | J8: =IF(F8=0,"",G8-H8) -> 0 | K8: =IF(F8=0,"",I8-G8) -> 0.071350034 | L8: =IF(F8=0,"",TEXT(G8,"0.0%")&" ["&TEXT(H8,"0.0%")&"–"&TEXT(I8,"0.0%")&"]") -> 0.0% [0.0%–7.1%] | M8: MolmoAct2 | N8: Concept/compositional transfer
A9: Counting | B9: π0.5 | C9: Complete benchmark | D9: 0 | E9: 50 | F9: =D9+E9 -> 50 | G9: =IF(F9=0,"",D9/F9) -> 0 | H9: =IF(F9=0,"",MAX(0,(G9+Guide!$B$4^2/(2*F9))/(1+Guide!$B$4^2/F9)-Guide!$B$4*SQRT(G9*(1-G9)/F9+Guide!$B$4^2/(4*F9^2))/(1+Guide!$B$4^2/F9))) -> 0 | I9: =IF(F9=0,"",MIN(1,(G9+Guide!$B$4^2/(2*F9))/(1+Guide!$B$4^2/F9)+Guide!$B$4*SQRT(G9*(1-G9)/F9+Guide!$B$4^2/(4*F9^2))/(1+Guide!$B$4^2/F9))) -> 0.071350034 | J9: =IF(F9=0,"",G9-H9) -> 0 | K9: =IF(F9=0,"",I9-G9) -> 0.071350034 | L9: =IF(F9=0,"",TEXT(G9,"0.0%")&" ["&TEXT(H9,"0.0%")&"–"&TEXT(I9,"0.0%")&"]") -> 0.0% [0.0%–7.1%] | M9: Pi0.5 | N9: Concept/compositional transfer
A10: Counting | B10: GR00T Vision | C10: Complete benchmark | D10: 0 | E10: 50 | F10: =D10+E10 -> 50 | G10: =IF(F10=0,"",D10/F10) -> 0 | H10: =IF(F10=0,"",MAX(0,(G10+Guide!$B$4^2/(2*F10))/(1+Guide!$B$4^2/F10)-Guide!$B$4*SQRT(G10*(1-G10)/F10+Guide!$B$4^2/(4*F10^2))/(1+Guide!$B$4^2/F10))) -> 0 | I10: =IF(F10=0,"",MIN(1,(G10+Guide!$B$4^2/(2*F10))/(1+Guide!$B$4^2/F10)+Guide!$B$4*SQRT(G10*(1-G10)/F10+Guide!$B$4^2/(4*F10^2))/(1+Guide!$B$4^2/F10))) -> 0.071350034 | J10: =IF(F10=0,"",G10-H10) -> 0 | K10: =IF(F10=0,"",I10-G10) -> 0.071350034 | L10: =IF(F10=0,"",TEXT(G10,"0.0%")&" ["&TEXT(H10,"0.0%")&"–"&TEXT(I10,"0.0%")&"]") -> 0.0% [0.0%–7.1%] | M10: GR00T Vision | N10: Concept/compositional transfer
A11: Ordinal Reference Ordering | B11: MolmoAct2 | C11: Complete benchmark | D11: 27 | E11: 23 | F11: =D11+E11 -> 50 | G11: =IF(F11=0,"",D11/F11) -> 0.54 | H11: =IF(F11=0,"",MAX(0,(G11+Guide!$B$4^2/(2*F11))/(1+Guide!$B$4^2/F11)-Guide!$B$4*SQRT(G11*(1-G11)/F11+Guide!$B$4^2/(4*F11^2))/(1+Guide!$B$4^2/F11))) -> 0.40398634 | I11: =IF(F11=0,"",MIN(1,(G11+Guide!$B$4^2/(2*F11))/(1+Guide!$B$4^2/F11)+Guide!$B$4*SQRT(G11*(1-G11)/F11+Guide!$B$4^2/(4*F11^2))/(1+Guide!$B$4^2/F11))) -> 0.67030565 | J11: =IF(F11=0,"",G11-H11) -> 0.13601366 | K11: =IF(F11=0,"",I11-G11) -> 0.13030565 | L11: =IF(F11=0,"",TEXT(G11,"0.0%")&" ["&TEXT(H11,"0.0%")&"–"&TEXT(I11,"0.0%")&"]") -> 54.0% [40.4%–67.0%] | M11: MolmoAct2 | N11: Concept/compositional transfer
A12: Ordinal Reference Ordering | B12: π0.5 | C12: Complete benchmark | D12: 23 | E12: 27 | F12: =D12+E12 -> 50 | G12: =IF(F12=0,"",D12/F12) -> 0.46 | H12: =IF(F12=0,"",MAX(0,(G12+Guide!$B$4^2/(2*F12))/(1+Guide!$B$4^2/F12)-Guide!$B$4*SQRT(G12*(1-G12)/F12+Guide!$B$4^2/(4*F12^2))/(1+Guide!$B$4^2/F12))) -> 0.32969435 | I12: =IF(F12=0,"",MIN(1,(G12+Guide!$B$4^2/(2*F12))/(1+Guide!$B$4^2/F12)+Guide!$B$4*SQRT(G12*(1-G12)/F12+Guide!$B$4^2/(4*F12^2))/(1+Guide!$B$4^2/F12))) -> 0.59601366 | J12: =IF(F12=0,"",G12-H12) -> 0.13030565 | K12: =IF(F12=0,"",I12-G12) -> 0.13601366 | L12: =IF(F12=0,"",TEXT(G12,"0.0%")&" ["&TEXT(H12,"0.0%")&"–"&TEXT(I12,"0.0%")&"]") -> 46.0% [33.0%–59.6%] | M12: Pi0.5 | N12: Concept/compositional transfer
A13: Ordinal Reference Ordering | B13: GR00T Vision | C13: Complete benchmark | D13: 21 | E13: 29 | F13: =D13+E13 -> 50 | G13: =IF(F13=0,"",D13/F13) -> 0.42 | H13: =IF(F13=0,"",MAX(0,(G13+Guide!$B$4^2/(2*F13))/(1+Guide!$B$4^2/F13)-Guide!$B$4*SQRT(G13*(1-G13)/F13+Guide!$B$4^2/(4*F13^2))/(1+Guide!$B$4^2/F13))) -> 0.29374797 | I13: =IF(F13=0,"",MIN(1,(G13+Guide!$B$4^2/(2*F13))/(1+Guide!$B$4^2/F13)+Guide!$B$4*SQRT(G13*(1-G13)/F13+Guide!$B$4^2/(4*F13^2))/(1+Guide!$B$4^2/F13))) -> 0.55766803 | J13: =IF(F13=0,"",G13-H13) -> 0.12625203 | K13: =IF(F13=0,"",I13-G13) -> 0.13766803 | L13: =IF(F13=0,"",TEXT(G13,"0.0%")&" ["&TEXT(H13,"0.0%")&"–"&TEXT(I13,"0.0%")&"]") -> 42.0% [29.4%–55.8%] | M13: GR00T Vision | N13: Concept/compositional transfer
A14: Relational Placement | B14: MolmoAct2 | C14: Complete benchmark | D14: 25 | E14: 25 | F14: =D14+E14 -> 50 | G14: =IF(F14=0,"",D14/F14) -> 0.5 | H14: =IF(F14=0,"",MAX(0,(G14+Guide!$B$4^2/(2*F14))/(1+Guide!$B$4^2/F14)-Guide!$B$4*SQRT(G14*(1-G14)/F14+Guide!$B$4^2/(4*F14^2))/(1+Guide!$B$4^2/F14))) -> 0.36644286 | I14: =IF(F14=0,"",MIN(1,(G14+Guide!$B$4^2/(2*F14))/(1+Guide!$B$4^2/F14)+Guide!$B$4*SQRT(G14*(1-G14)/F14+Guide!$B$4^2/(4*F14^2))/(1+Guide!$B$4^2/F14))) -> 0.63355714 | J14: =IF(F14=0,"",G14-H14) -> 0.13355714 | K14: =IF(F14=0,"",I14-G14) -> 0.13355714 | L14: =IF(F14=0,"",TEXT(G14,"0.0%")&" ["&TEXT(H14,"0.0%")&"–"&TEXT(I14,"0.0%")&"]") -> 50.0% [36.6%–63.4%] | M14: MolmoAct2 | N14: Concept/compositional transfer
A15: Relational Placement | B15: π0.5 | C15: Complete benchmark | D15: 36 | E15: 14 | F15: =D15+E15 -> 50 | G15: =IF(F15=0,"",D15/F15) -> 0.72 | H15: =IF(F15=0,"",MAX(0,(G15+Guide!$B$4^2/(2*F15))/(1+Guide!$B$4^2/F15)-Guide!$B$4*SQRT(G15*(1-G15)/F15+Guide!$B$4^2/(4*F15^2))/(1+Guide!$B$4^2/F15))) -> 0.58334613 | I15: =IF(F15=0,"",MIN(1,(G15+Guide!$B$4^2/(2*F15))/(1+Guide!$B$4^2/F15)+Guide!$B$4*SQRT(G15*(1-G15)/F15+Guide!$B$4^2/(4*F15^2))/(1+Guide!$B$4^2/F15))) -> 0.82525986 | J15: =IF(F15=0,"",G15-H15) -> 0.13665387 | K15: =IF(F15=0,"",I15-G15) -> 0.10525986 | L15: =IF(F15=0,"",TEXT(G15,"0.0%")&" ["&TEXT(H15,"0.0%")&"–"&TEXT(I15,"0.0%")&"]") -> 72.0% [58.3%–82.5%] | M15: Pi0.5 | N15: Concept/compositional transfer
A16: Relational Placement | B16: GR00T Vision | C16: Complete benchmark | D16: 39 | E16: 11 | F16: =D16+E16 -> 50 | G16: =IF(F16=0,"",D16/F16) -> 0.78 | H16: =IF(F16=0,"",MAX(0,(G16+Guide!$B$4^2/(2*F16))/(1+Guide!$B$4^2/F16)-Guide!$B$4*SQRT(G16*(1-G16)/F16+Guide!$B$4^2/(4*F16^2))/(1+Guide!$B$4^2/F16))) -> 0.64758184 | I16: =IF(F16=0,"",MIN(1,(G16+Guide!$B$4^2/(2*F16))/(1+Guide!$B$4^2/F16)+Guide!$B$4*SQRT(G16*(1-G16)/F16+Guide!$B$4^2/(4*F16^2))/(1+Guide!$B$4^2/F16))) -> 0.87246214 | J16: =IF(F16=0,"",G16-H16) -> 0.13241816 | K16: =IF(F16=0,"",I16-G16) -> 0.092462138 | L16: =IF(F16=0,"",TEXT(G16,"0.0%")&" ["&TEXT(H16,"0.0%")&"–"&TEXT(I16,"0.0%")&"]") -> 78.0% [64.8%–87.2%] | M16: GR00T Vision | N16: Concept/compositional transfer
... A22: Size Recognition | B22: GR00T Vision | C22: Complete benchmark | D22: 29 | E22: 21 | F22: =D22+E22 -> 50 | G22: =IF(F22=0,"",D22/F22) -> 0.58 | H22: =IF(F22=0,"",MAX(0,(G22+Guide!$B$4^2/(2*F22))/(1+Guide!$B$4^2/F22)-Guide!$B$4*SQRT(G22*(1-G22)/F22+Guide!$B$4^2/(4*F22^2))/(1+Guide!$B$4^2/F22))) -> 0.44233197 | I22: =IF(F22=0,"",MIN(1,(G22+Guide!$B$4^2/(2*F22))/(1+Guide!$B$4^2/F22)+Guide!$B$4*SQRT(G22*(1-G22)/F22+Guide!$B$4^2/(4*F22^2))/(1+Guide!$B$4^2/F22))) -> 0.70625203 | J22: =IF(F22=0,"",G22-H22) -> 0.13766803 | K22: =IF(F22=0,"",I22-G22) -> 0.12625203 | L22: =IF(F22=0,"",TEXT(G22,"0.0%")&" ["&TEXT(H22,"0.0%")&"–"&TEXT(I22,"0.0%")&"]") -> 58.0% [44.2%–70.6%] | M22: GR00T Vision | N22: Concept/compositional transfer

Sheet Matched Data
A1: Matched Manipulation Controls by Task
A2: Three complete models; 20 trials per task and model. These controls separate spatial grounding failures from basic manipulation failures.
A4: Task / Track | B4: Model | C4: Evaluation scope | D4: Success | E4: Failure | F4: Scored | G4: Success rate | H4: CI lower | I4: CI upper | J4: Lower error | K4: Upper error | L4: Wilson 95% CI | M4: Source sheet | N4: Source condition(s) | O4: Notes
A5: State Recognition | B5: MolmoAct2 | C5: Complete benchmark | D5: 20 | E5: 0 | F5: =D5+E5 -> 20 | G5: =IF(F5=0,"",D5/F5) -> 1 | H5: =IF(F5=0,"",MAX(0,(G5+Guide!$B$4^2/(2*F5))/(1+Guide!$B$4^2/F5)-Guide!$B$4*SQRT(G5*(1-G5)/F5+Guide!$B$4^2/(4*F5^2))/(1+Guide!$B$4^2/F5))) -> 0.83886987 | I5: =IF(F5=0,"",MIN(1,(G5+Guide!$B$4^2/(2*F5))/(1+Guide!$B$4^2/F5)+Guide!$B$4*SQRT(G5*(1-G5)/F5+Guide!$B$4^2/(4*F5^2))/(1+Guide!$B$4^2/F5))) -> 1 | J5: =IF(F5=0,"",G5-H5) -> 0.16113013 | K5: =IF(F5=0,"",I5-G5) -> 0 | L5: =IF(F5=0,"",TEXT(G5,"0.0%")&" ["&TEXT(H5,"0.0%")&"–"&TEXT(I5,"0.0%")&"]") -> 100.0% [83.9%–100.0%] | M5: MolmoAct2 | N5: Matched manipulation control
A6: State Recognition | B6: π0.5 | C6: Complete benchmark | D6: 18 | E6: 2 | F6: =D6+E6 -> 20 | G6: =IF(F6=0,"",D6/F6) -> 0.9 | H6: =IF(F6=0,"",MAX(0,(G6+Guide!$B$4^2/(2*F6))/(1+Guide!$B$4^2/F6)-Guide!$B$4*SQRT(G6*(1-G6)/F6+Guide!$B$4^2/(4*F6^2))/(1+Guide!$B$4^2/F6))) -> 0.69896179 | I6: =IF(F6=0,"",MIN(1,(G6+Guide!$B$4^2/(2*F6))/(1+Guide!$B$4^2/F6)+Guide!$B$4*SQRT(G6*(1-G6)/F6+Guide!$B$4^2/(4*F6^2))/(1+Guide!$B$4^2/F6))) -> 0.97213411 | J6: =IF(F6=0,"",G6-H6) -> 0.20103821 | K6: =IF(F6=0,"",I6-G6) -> 0.072134106 | L6: =IF(F6=0,"",TEXT(G6,"0.0%")&" ["&TEXT(H6,"0.0%")&"–"&TEXT(I6,"0.0%")&"]") -> 90.0% [69.9%–97.2%] | M6: Pi0.5 | N6: Matched manipulation control
A7: State Recognition | B7: GR00T Vision | C7: Complete benchmark | D7: 19 | E7: 1 | F7: =D7+E7 -> 20 | G7: =IF(F7=0,"",D7/F7) -> 0.95 | H7: =IF(F7=0,"",MAX(0,(G7+Guide!$B$4^2/(2*F7))/(1+Guide!$B$4^2/F7)-Guide!$B$4*SQRT(G7*(1-G7)/F7+Guide!$B$4^2/(4*F7^2))/(1+Guide!$B$4^2/F7))) -> 0.76386411 | I7: =IF(F7=0,"",MIN(1,(G7+Guide!$B$4^2/(2*F7))/(1+Guide!$B$4^2/F7)+Guide!$B$4*SQRT(G7*(1-G7)/F7+Guide!$B$4^2/(4*F7^2))/(1+Guide!$B$4^2/F7))) -> 0.99111878 | J7: =IF(F7=0,"",G7-H7) -> 0.18613589 | K7: =IF(F7=0,"",I7-G7) -> 0.041118781 | L7: =IF(F7=0,"",TEXT(G7,"0.0%")&" ["&TEXT(H7,"0.0%")&"–"&TEXT(I7,"0.0%")&"]") -> 95.0% [76.4%–99.1%] | M7: GR00T Vision | N7: Matched manipulation control
A8: Counting | B8: MolmoAct2 | C8: Complete benchmark | D8: 16 | E8: 4 | F8: =D8+E8 -> 20 | G8: =IF(F8=0,"",D8/F8) -> 0.8 | H8: =IF(F8=0,"",MAX(0,(G8+Guide!$B$4^2/(2*F8))/(1+Guide!$B$4^2/F8)-Guide!$B$4*SQRT(G8*(1-G8)/F8+Guide!$B$4^2/(4*F8^2))/(1+Guide!$B$4^2/F8))) -> 0.58397828 | I8: =IF(F8=0,"",MIN(1,(G8+Guide!$B$4^2/(2*F8))/(1+Guide!$B$4^2/F8)+Guide!$B$4*SQRT(G8*(1-G8)/F8+Guide!$B$4^2/(4*F8^2))/(1+Guide!$B$4^2/F8))) -> 0.91934365 | J8: =IF(F8=0,"",G8-H8) -> 0.21602172 | K8: =IF(F8=0,"",I8-G8) -> 0.11934365 | L8: =IF(F8=0,"",TEXT(G8,"0.0%")&" ["&TEXT(H8,"0.0%")&"–"&TEXT(I8,"0.0%")&"]") -> 80.0% [58.4%–91.9%] | M8: MolmoAct2 | N8: Matched manipulation control
A9: Counting | B9: π0.5 | C9: Complete benchmark | D9: 11 | E9: 9 | F9: =D9+E9 -> 20 | G9: =IF(F9=0,"",D9/F9) -> 0.55 | H9: =IF(F9=0,"",MAX(0,(G9+Guide!$B$4^2/(2*F9))/(1+Guide!$B$4^2/F9)-Guide!$B$4*SQRT(G9*(1-G9)/F9+Guide!$B$4^2/(4*F9^2))/(1+Guide!$B$4^2/F9))) -> 0.34208201 | I9: =IF(F9=0,"",MIN(1,(G9+Guide!$B$4^2/(2*F9))/(1+Guide!$B$4^2/F9)+Guide!$B$4*SQRT(G9*(1-G9)/F9+Guide!$B$4^2/(4*F9^2))/(1+Guide!$B$4^2/F9))) -> 0.74180498 | J9: =IF(F9=0,"",G9-H9) -> 0.20791799 | K9: =IF(F9=0,"",I9-G9) -> 0.19180498 | L9: =IF(F9=0,"",TEXT(G9,"0.0%")&" ["&TEXT(H9,"0.0%")&"–"&TEXT(I9,"0.0%")&"]") -> 55.0% [34.2%–74.2%] | M9: Pi0.5 | N9: Matched manipulation control
A10: Counting | B10: GR00T Vision | C10: Complete benchmark | D10: 12 | E10: 8 | F10: =D10+E10 -> 20 | G10: =IF(F10=0,"",D10/F10) -> 0.6 | H10: =IF(F10=0,"",MAX(0,(G10+Guide!$B$4^2/(2*F10))/(1+Guide!$B$4^2/F10)-Guide!$B$4*SQRT(G10*(1-G10)/F10+Guide!$B$4^2/(4*F10^2))/(1+Guide!$B$4^2/F10))) -> 0.38657794 | I10: =IF(F10=0,"",MIN(1,(G10+Guide!$B$4^2/(2*F10))/(1+Guide!$B$4^2/F10)+Guide!$B$4*SQRT(G10*(1-G10)/F10+Guide!$B$4^2/(4*F10^2))/(1+Guide!$B$4^2/F10))) -> 0.78119603 | J10: =IF(F10=0,"",G10-H10) -> 0.21342206 | K10: =IF(F10=0,"",I10-G10) -> 0.18119603 | L10: =IF(F10=0,"",TEXT(G10,"0.0%")&" ["&TEXT(H10,"0.0%")&"–"&TEXT(I10,"0.0%")&"]") -> 60.0% [38.7%–78.1%] | M10: GR00T Vision | N10: Matched manipulation control
A11: Ordinal Reference Ordering | B11: MolmoAct2 | C11: Complete benchmark | D11: 17 | E11: 3 | F11: =D11+E11 -> 20 | G11: =IF(F11=0,"",D11/F11) -> 0.85 | H11: =IF(F11=0,"",MAX(0,(G11+Guide!$B$4^2/(2*F11))/(1+Guide!$B$4^2/F11)-Guide!$B$4*SQRT(G11*(1-G11)/F11+Guide!$B$4^2/(4*F11^2))/(1+Guide!$B$4^2/F11))) -> 0.6395767 | I11: =IF(F11=0,"",MIN(1,(G11+Guide!$B$4^2/(2*F11))/(1+Guide!$B$4^2/F11)+Guide!$B$4*SQRT(G11*(1-G11)/F11+Guide!$B$4^2/(4*F11^2))/(1+Guide!$B$4^2/F11))) -> 0.94763221 | J11: =IF(F11=0,"",G11-H11) -> 0.2104233 | K11: =IF(F11=0,"",I11-G11) -> 0.097632208 | L11: =IF(F11=0,"",TEXT(G11,"0.0%")&" ["&TEXT(H11,"0.0%")&"–"&TEXT(I11,"0.0%")&"]") -> 85.0% [64.0%–94.8%] | M11: MolmoAct2 | N11: Matched manipulation control
A12: Ordinal Reference Ordering | B12: π0.5 | C12: Complete benchmark | D12: 20 | E12: 0 | F12: =D12+E12 -> 20 | G12: =IF(F12=0,"",D12/F12) -> 1 | H12: =IF(F12=0,"",MAX(0,(G12+Guide!$B$4^2/(2*F12))/(1+Guide!$B$4^2/F12)-Guide!$B$4*SQRT(G12*(1-G12)/F12+Guide!$B$4^2/(4*F12^2))/(1+Guide!$B$4^2/F12))) -> 0.83886987 | I12: =IF(F12=0,"",MIN(1,(G12+Guide!$B$4^2/(2*F12))/(1+Guide!$B$4^2/F12)+Guide!$B$4*SQRT(G12*(1-G12)/F12+Guide!$B$4^2/(4*F12^2))/(1+Guide!$B$4^2/F12))) -> 1 | J12: =IF(F12=0,"",G12-H12) -> 0.16113013 | K12: =IF(F12=0,"",I12-G12) -> 0 | L12: =IF(F12=0,"",TEXT(G12,"0.0%")&" ["&TEXT(H12,"0.0%")&"–"&TEXT(I12,"0.0%")&"]") -> 100.0% [83.9%–100.0%] | M12: Pi0.5 | N12: Matched manipulation control
A13: Ordinal Reference Ordering | B13: GR00T Vision | C13: Complete benchmark | D13: 19 | E13: 1 | F13: =D13+E13 -> 20 | G13: =IF(F13=0,"",D13/F13) -> 0.95 | H13: =IF(F13=0,"",MAX(0,(G13+Guide!$B$4^2/(2*F13))/(1+Guide!$B$4^2/F13)-Guide!$B$4*SQRT(G13*(1-G13)/F13+Guide!$B$4^2/(4*F13^2))/(1+Guide!$B$4^2/F13))) -> 0.76386411 | I13: =IF(F13=0,"",MIN(1,(G13+Guide!$B$4^2/(2*F13))/(1+Guide!$B$4^2/F13)+Guide!$B$4*SQRT(G13*(1-G13)/F13+Guide!$B$4^2/(4*F13^2))/(1+Guide!$B$4^2/F13))) -> 0.99111878 | J13: =IF(F13=0,"",G13-H13) -> 0.18613589 | K13: =IF(F13=0,"",I13-G13) -> 0.041118781 | L13: =IF(F13=0,"",TEXT(G13,"0.0%")&" ["&TEXT(H13,"0.0%")&"–"&TEXT(I13,"0.0%")&"]") -> 95.0% [76.4%–99.1%] | M13: GR00T Vision | N13: Matched manipulation control
A14: Relational Placement | B14: MolmoAct2 | C14: Complete benchmark | D14: 17 | E14: 3 | F14: =D14+E14 -> 20 | G14: =IF(F14=0,"",D14/F14) -> 0.85 | H14: =IF(F14=0,"",MAX(0,(G14+Guide!$B$4^2/(2*F14))/(1+Guide!$B$4^2/F14)-Guide!$B$4*SQRT(G14*(1-G14)/F14+Guide!$B$4^2/(4*F14^2))/(1+Guide!$B$4^2/F14))) -> 0.6395767 | I14: =IF(F14=0,"",MIN(1,(G14+Guide!$B$4^2/(2*F14))/(1+Guide!$B$4^2/F14)+Guide!$B$4*SQRT(G14*(1-G14)/F14+Guide!$B$4^2/(4*F14^2))/(1+Guide!$B$4^2/F14))) -> 0.94763221 | J14: =IF(F14=0,"",G14-H14) -> 0.2104233 | K14: =IF(F14=0,"",I14-G14) -> 0.097632208 | L14: =IF(F14=0,"",TEXT(G14,"0.0%")&" ["&TEXT(H14,"0.0%")&"–"&TEXT(I14,"0.0%")&"]") -> 85.0% [64.0%–94.8%] | M14: MolmoAct2 | N14: Matched manipulation control
A15: Relational Placement | B15: π0.5 | C15: Complete benchmark | D15: 18 | E15: 2 | F15: =D15+E15 -> 20 | G15: =IF(F15=0,"",D15/F15) -> 0.9 | H15: =IF(F15=0,"",MAX(0,(G15+Guide!$B$4^2/(2*F15))/(1+Guide!$B$4^2/F15)-Guide!$B$4*SQRT(G15*(1-G15)/F15+Guide!$B$4^2/(4*F15^2))/(1+Guide!$B$4^2/F15))) -> 0.69896179 | I15: =IF(F15=0,"",MIN(1,(G15+Guide!$B$4^2/(2*F15))/(1+Guide!$B$4^2/F15)+Guide!$B$4*SQRT(G15*(1-G15)/F15+Guide!$B$4^2/(4*F15^2))/(1+Guide!$B$4^2/F15))) -> 0.97213411 | J15: =IF(F15=0,"",G15-H15) -> 0.20103821 | K15: =IF(F15=0,"",I15-G15) -> 0.072134106 | L15: =IF(F15=0,"",TEXT(G15,"0.0%")&" ["&TEXT(H15,"0.0%")&"–"&TEXT(I15,"0.0%")&"]") -> 90.0% [69.9%–97.2%] | M15: Pi0.5 | N15: Matched manipulation control
A16: Relational Placement | B16: GR00T Vision | C16: Complete benchmark | D16: 17 | E16: 3 | F16: =D16+E16 -> 20 | G16: =IF(F16=0,"",D16/F16) -> 0.85 | H16: =IF(F16=0,"",MAX(0,(G16+Guide!$B$4^2/(2*F16))/(1+Guide!$B$4^2/F16)-Guide!$B$4*SQRT(G16*(1-G16)/F16+Guide!$B$4^2/(4*F16^2))/(1+Guide!$B$4^2/F16))) -> 0.6395767 | I16: =IF(F16=0,"",MIN(1,(G16+Guide!$B$4^2/(2*F16))/(1+Guide!$B$4^2/F16)+Guide!$B$4*SQRT(G16*(1-G16)/F16+Guide!$B$4^2/(4*F16^2))/(1+Guide!$B$4^2/F16))) -> 0.94763221 | J16: =IF(F16=0,"",G16-H16) -> 0.2104233 | K16: =IF(F16=0,"",I16-G16) -> 0.097632208 | L16: =IF(F16=0,"",TEXT(G16,"0.0%")&" ["&TEXT(H16,"0.0%")&"–"&TEXT(I16,"0.0%")&"]") -> 85.0% [64.0%–94.8%] | M16: GR00T Vision | N16: Matched manipulation control
... A22: Size Recognition | B22: GR00T Vision | C22: Complete benchmark | D22: 19 | E22: 1 | F22: =D22+E22 -> 20 | G22: =IF(F22=0,"",D22/F22) -> 0.95 | H22: =IF(F22=0,"",MAX(0,(G22+Guide!$B$4^2/(2*F22))/(1+Guide!$B$4^2/F22)-Guide!$B$4*SQRT(G22*(1-G22)/F22+Guide!$B$4^2/(4*F22^2))/(1+Guide!$B$4^2/F22))) -> 0.76386411 | I22: =IF(F22=0,"",MIN(1,(G22+Guide!$B$4^2/(2*F22))/(1+Guide!$B$4^2/F22)+Guide!$B$4*SQRT(G22*(1-G22)/F22+Guide!$B$4^2/(4*F22^2))/(1+Guide!$B$4^2/F22))) -> 0.99111878 | J22: =IF(F22=0,"",G22-H22) -> 0.18613589 | K22: =IF(F22=0,"",I22-G22) -> 0.041118781 | L22: =IF(F22=0,"",TEXT(G22,"0.0%")&" ["&TEXT(H22,"0.0%")&"–"&TEXT(I22,"0.0%")&"]") -> 95.0% [76.4%–99.1%] | M22: GR00T Vision | N22: Matched manipulation control

Sheet Diagnostics
A1: Diagnostic Evaluation Results
A2: All rows include exact Wilson 95% intervals. Aggregate rows pool only the applicable tasks listed in the accompanying notes.
A4: Diagnostic / task | B4: Model | C4: Evaluation scope | D4: Success | E4: Failure | F4: Scored | G4: Success rate | H4: CI lower | I4: CI upper | J4: Lower error | K4: Upper error | L4: Wilson 95% CI | M4: Source sheet | N4: Source condition(s) | O4: Notes
A5: Novel prompt paraphrases — All applicable tasks | B5: MolmoAct2 | C5: Complete benchmark | D5: 30 | E5: 30 | F5: =D5+E5 -> 60 | G5: =IF(F5=0,"",D5/F5) -> 0.5 | H5: =IF(F5=0,"",MAX(0,(G5+Guide!$B$4^2/(2*F5))/(1+Guide!$B$4^2/F5)-Guide!$B$4*SQRT(G5*(1-G5)/F5+Guide!$B$4^2/(4*F5^2))/(1+Guide!$B$4^2/F5))) -> 0.37734812 | I5: =IF(F5=0,"",MIN(1,(G5+Guide!$B$4^2/(2*F5))/(1+Guide!$B$4^2/F5)+Guide!$B$4*SQRT(G5*(1-G5)/F5+Guide!$B$4^2/(4*F5^2))/(1+Guide!$B$4^2/F5))) -> 0.62265188 | J5: =IF(F5=0,"",G5-H5) -> 0.12265188 | K5: =IF(F5=0,"",I5-G5) -> 0.12265188 | L5: =IF(F5=0,"",TEXT(G5,"0.0%")&" ["&TEXT(H5,"0.0%")&"–"&TEXT(I5,"0.0%")&"]") -> 50.0% [37.7%–62.3%] | M5: MolmoAct2 | N5: Language robustness — transfer paraphrases | O5: Paraphrases of novel spatial-concept prompts.
A6: Novel prompt paraphrases — All applicable tasks | B6: π0.5 | C6: Complete benchmark | D6: 25 | E6: 35 | F6: =D6+E6 -> 60 | G6: =IF(F6=0,"",D6/F6) -> 0.41666667 | H6: =IF(F6=0,"",MAX(0,(G6+Guide!$B$4^2/(2*F6))/(1+Guide!$B$4^2/F6)-Guide!$B$4*SQRT(G6*(1-G6)/F6+Guide!$B$4^2/(4*F6^2))/(1+Guide!$B$4^2/F6))) -> 0.30064086 | I6: =IF(F6=0,"",MIN(1,(G6+Guide!$B$4^2/(2*F6))/(1+Guide!$B$4^2/F6)+Guide!$B$4*SQRT(G6*(1-G6)/F6+Guide!$B$4^2/(4*F6^2))/(1+Guide!$B$4^2/F6))) -> 0.54272146 | J6: =IF(F6=0,"",G6-H6) -> 0.1160258 | K6: =IF(F6=0,"",I6-G6) -> 0.12605479 | L6: =IF(F6=0,"",TEXT(G6,"0.0%")&" ["&TEXT(H6,"0.0%")&"–"&TEXT(I6,"0.0%")&"]") -> 41.7% [30.1%–54.3%] | M6: Pi0.5 | N6: Language robustness — transfer paraphrases | O6: Paraphrases of novel spatial-concept prompts.
A7: Novel prompt paraphrases — All applicable tasks | B7: GR00T Vision | C7: Complete benchmark | D7: 23 | E7: 37 | F7: =D7+E7 -> 60 | G7: =IF(F7=0,"",D7/F7) -> 0.38333333 | H7: =IF(F7=0,"",MAX(0,(G7+Guide!$B$4^2/(2*F7))/(1+Guide!$B$4^2/F7)-Guide!$B$4*SQRT(G7*(1-G7)/F7+Guide!$B$4^2/(4*F7^2))/(1+Guide!$B$4^2/F7))) -> 0.2708809 | I7: =IF(F7=0,"",MIN(1,(G7+Guide!$B$4^2/(2*F7))/(1+Guide!$B$4^2/F7)+Guide!$B$4*SQRT(G7*(1-G7)/F7+Guide!$B$4^2/(4*F7^2))/(1+Guide!$B$4^2/F7))) -> 0.50982635 | J7: =IF(F7=0,"",G7-H7) -> 0.11245244 | K7: =IF(F7=0,"",I7-G7) -> 0.12649302 | L7: =IF(F7=0,"",TEXT(G7,"0.0%")&" ["&TEXT(H7,"0.0%")&"–"&TEXT(I7,"0.0%")&"]") -> 38.3% [27.1%–51.0%] | M7: GR00T Vision | N7: Language robustness — transfer paraphrases | O7: Paraphrases of novel spatial-concept prompts.
A8: Novel prompt paraphrases — State Recognition | B8: MolmoAct2 | C8: Complete benchmark | D8: 8 | E8: 2 | F8: =D8+E8 -> 10 | G8: =IF(F8=0,"",D8/F8) -> 0.8 | H8: =IF(F8=0,"",MAX(0,(G8+Guide!$B$4^2/(2*F8))/(1+Guide!$B$4^2/F8)-Guide!$B$4*SQRT(G8*(1-G8)/F8+Guide!$B$4^2/(4*F8^2))/(1+Guide!$B$4^2/F8))) -> 0.49015685 | I8: =IF(F8=0,"",MIN(1,(G8+Guide!$B$4^2/(2*F8))/(1+Guide!$B$4^2/F8)+Guide!$B$4*SQRT(G8*(1-G8)/F8+Guide!$B$4^2/(4*F8^2))/(1+Guide!$B$4^2/F8))) -> 0.94331905 | J8: =IF(F8=0,"",G8-H8) -> 0.30984315 | K8: =IF(F8=0,"",I8-G8) -> 0.14331905 | L8: =IF(F8=0,"",TEXT(G8,"0.0%")&" ["&TEXT(H8,"0.0%")&"–"&TEXT(I8,"0.0%")&"]") -> 80.0% [49.0%–94.3%] | M8: MolmoAct2 | N8: Language robustness — transfer paraphrases | O8: Paraphrases of novel spatial-concept prompts.
A9: Novel prompt paraphrases — State Recognition | B9: π0.5 | C9: Complete benchmark | D9: 3 | E9: 7 | F9: =D9+E9 -> 10 | G9: =IF(F9=0,"",D9/F9) -> 0.3 | H9: =IF(F9=0,"",MAX(0,(G9+Guide!$B$4^2/(2*F9))/(1+Guide!$B$4^2/F9)-Guide!$B$4*SQRT(G9*(1-G9)/F9+Guide!$B$4^2/(4*F9^2))/(1+Guide!$B$4^2/F9))) -> 0.10778929 | I9: =IF(F9=0,"",MIN(1,(G9+Guide!$B$4^2/(2*F9))/(1+Guide!$B$4^2/F9)+Guide!$B$4*SQRT(G9*(1-G9)/F9+Guide!$B$4^2/(4*F9^2))/(1+Guide!$B$4^2/F9))) -> 0.60322678 | J9: =IF(F9=0,"",G9-H9) -> 0.19221071 | K9: =IF(F9=0,"",I9-G9) -> 0.30322678 | L9: =IF(F9=0,"",TEXT(G9,"0.0%")&" ["&TEXT(H9,"0.0%")&"–"&TEXT(I9,"0.0%")&"]") -> 30.0% [10.8%–60.3%] | M9: Pi0.5 | N9: Language robustness — transfer paraphrases | O9: Paraphrases of novel spatial-concept prompts.
A10: Novel prompt paraphrases — State Recognition | B10: GR00T Vision | C10: Complete benchmark | D10: 4 | E10: 6 | F10: =D10+E10 -> 10 | G10: =IF(F10=0,"",D10/F10) -> 0.4 | H10: =IF(F10=0,"",MAX(0,(G10+Guide!$B$4^2/(2*F10))/(1+Guide!$B$4^2/F10)-Guide!$B$4*SQRT(G10*(1-G10)/F10+Guide!$B$4^2/(4*F10^2))/(1+Guide!$B$4^2/F10))) -> 0.16817758 | I10: =IF(F10=0,"",MIN(1,(G10+Guide!$B$4^2/(2*F10))/(1+Guide!$B$4^2/F10)+Guide!$B$4*SQRT(G10*(1-G10)/F10+Guide!$B$4^2/(4*F10^2))/(1+Guide!$B$4^2/F10))) -> 0.68733045 | J10: =IF(F10=0,"",G10-H10) -> 0.23182242 | K10: =IF(F10=0,"",I10-G10) -> 0.28733045 | L10: =IF(F10=0,"",TEXT(G10,"0.0%")&" ["&TEXT(H10,"0.0%")&"–"&TEXT(I10,"0.0%")&"]") -> 40.0% [16.8%–68.7%] | M10: GR00T Vision | N10: Language robustness — transfer paraphrases | O10: Paraphrases of novel spatial-concept prompts.
A11: Novel prompt paraphrases — Counting | B11: MolmoAct2 | C11: Complete benchmark | D11: 0 | E11: 10 | F11: =D11+E11 -> 10 | G11: =IF(F11=0,"",D11/F11) -> 0 | H11: =IF(F11=0,"",MAX(0,(G11+Guide!$B$4^2/(2*F11))/(1+Guide!$B$4^2/F11)-Guide!$B$4*SQRT(G11*(1-G11)/F11+Guide!$B$4^2/(4*F11^2))/(1+Guide!$B$4^2/F11))) -> 0 | I11: =IF(F11=0,"",MIN(1,(G11+Guide!$B$4^2/(2*F11))/(1+Guide!$B$4^2/F11)+Guide!$B$4*SQRT(G11*(1-G11)/F11+Guide!$B$4^2/(4*F11^2))/(1+Guide!$B$4^2/F11))) -> 0.27754017 | J11: =IF(F11=0,"",G11-H11) -> 0 | K11: =IF(F11=0,"",I11-G11) -> 0.27754017 | L11: =IF(F11=0,"",TEXT(G11,"0.0%")&" ["&TEXT(H11,"0.0%")&"–"&TEXT(I11,"0.0%")&"]") -> 0.0% [0.0%–27.8%] | M11: MolmoAct2 | N11: Language robustness — transfer paraphrases | O11: Paraphrases of novel spatial-concept prompts.
